{
  "overall_status": "CR\u00cdTICO",
  "status_emoji": "\ud83d\udd34",
  "success_rate": 75.0,
  "total_tests": 28,
  "tests_passed": 21,
  "tests_failed": 7,
  "warnings": 1,
  "details": [
    {
      "test": "Python Version",
      "status": "PASS",
      "details": "Python 3.13.4",
      "timestamp": "2025-08-29 20:20:51"
    },
    {
      "test": "Package flask",
      "status": "PASS",
      "details": "",
      "timestamp": "2025-08-29 20:20:52"
    },
    {
      "test": "Package flask_sqlalchemy",
      "status": "PASS",
      "details": "",
      "timestamp": "2025-08-29 20:20:52"
    },
    {
      "test": "Package flask_jwt_extended",
      "status": "PASS",
      "details": "",
      "timestamp": "2025-08-29 20:20:53"
    },
    {
      "test": "Package scikit-learn",
      "status": "FAIL",
      "details": "Paquete scikit-learn no instalado",
      "timestamp": "2025-08-29 20:20:53"
    },
    {
      "test": "Package numpy",
      "status": "PASS",
      "details": "",
      "timestamp": "2025-08-29 20:20:53"
    },
    {
      "test": "Package redis",
      "status": "PASS",
      "details": "",
      "timestamp": "2025-08-29 20:20:53"
    },
    {
      "test": "Package psycopg2",
      "status": "PASS",
      "details": "",
      "timestamp": "2025-08-29 20:20:53"
    },
    {
      "test": "File app/__init__.py",
      "status": "PASS",
      "details": "",
      "timestamp": "2025-08-29 20:20:53"
    },
    {
      "test": "File app/core/config.py",
      "status": "PASS",
      "details": "",
      "timestamp": "2025-08-29 20:20:53"
    },
    {
      "test": "File app/core/database.py",
      "status": "PASS",
      "details": "",
      "timestamp": "2025-08-29 20:20:53"
    },
    {
      "test": "File app/models/user.py",
      "status": "PASS",
      "details": "",
      "timestamp": "2025-08-29 20:20:53"
    },
    {
      "test": "File app/models/product.py",
      "status": "PASS",
      "details": "",
      "timestamp": "2025-08-29 20:20:53"
    },
    {
      "test": "File app/api/v1/routes.py",
      "status": "PASS",
      "details": "",
      "timestamp": "2025-08-29 20:20:53"
    },
    {
      "test": "File app/api/v2/routes.py",
      "status": "PASS",
      "details": "",
      "timestamp": "2025-08-29 20:20:53"
    },
    {
      "test": "File requirements.txt",
      "status": "PASS",
      "details": "",
      "timestamp": "2025-08-29 20:20:53"
    },
    {
      "test": "File run_server.py",
      "status": "PASS",
      "details": "",
      "timestamp": "2025-08-29 20:20:53"
    },
    {
      "test": "File README.md",
      "status": "PASS",
      "details": "",
      "timestamp": "2025-08-29 20:20:53"
    },
    {
      "test": "Secret Key",
      "status": "PASS",
      "details": "SECRET_KEY configurado",
      "timestamp": "2025-08-29 20:20:53"
    },
    {
      "test": "JWT Secret Key",
      "status": "PASS",
      "details": "JWT_SECRET_KEY configurado",
      "timestamp": "2025-08-29 20:20:53"
    },
    {
      "test": "Database Connection",
      "status": "PASS",
      "details": "SQLite - 7 tablas encontradas",
      "timestamp": "2025-08-29 20:20:53"
    },
    {
      "test": "Security Audit",
      "status": "WARNING",
      "details": "Auditor\u00eda con advertencias",
      "timestamp": "2025-08-29 20:20:53"
    },
    {
      "test": "Test Server Start",
      "status": "PASS",
      "details": "Servidor iniciado en puerto 5000",
      "timestamp": "2025-08-29 20:20:58"
    },
    {
      "test": "API Root endpoint",
      "status": "FAIL",
      "details": "Error: HTTPConnectionPool(host='localhost', port=5000): Max retries exceeded with url: / (Caused by NewConnectionError('<urllib3.connection.HTTPConnection object at 0x0000017CA9094590>: Failed to establish a new connection: [WinError 10061] No se puede establecer una conexi\u00f3n ya que el equipo de destino deneg\u00f3 expresamente dicha conexi\u00f3n'))",
      "timestamp": "2025-08-29 20:21:05"
    },
    {
      "test": "API Health check",
      "status": "FAIL",
      "details": "Error: HTTPConnectionPool(host='localhost', port=5000): Max retries exceeded with url: /health (Caused by NewConnectionError('<urllib3.connection.HTTPConnection object at 0x0000017CA8FD2D50>: Failed to establish a new connection: [WinError 10061] No se puede establecer una conexi\u00f3n ya que el equipo de destino deneg\u00f3 expresamente dicha conexi\u00f3n'))",
      "timestamp": "2025-08-29 20:21:09"
    },
    {
      "test": "API API v1 info",
      "status": "FAIL",
      "details": "Error: HTTPConnectionPool(host='localhost', port=5000): Max retries exceeded with url: /api/v1/ (Caused by NewConnectionError('<urllib3.connection.HTTPConnection object at 0x0000017CA8FD3610>: Failed to establish a new connection: [WinError 10061] No se puede establecer una conexi\u00f3n ya que el equipo de destino deneg\u00f3 expresamente dicha conexi\u00f3n'))",
      "timestamp": "2025-08-29 20:21:13"
    },
    {
      "test": "API API v2 info",
      "status": "FAIL",
      "details": "Error: HTTPConnectionPool(host='localhost', port=5000): Max retries exceeded with url: /api/v2/ (Caused by NewConnectionError('<urllib3.connection.HTTPConnection object at 0x0000017CA8FCFCE0>: Failed to establish a new connection: [WinError 10061] No se puede establecer una conexi\u00f3n ya que el equipo de destino deneg\u00f3 expresamente dicha conexi\u00f3n'))",
      "timestamp": "2025-08-29 20:21:17"
    },
    {
      "test": "API AI health check",
      "status": "FAIL",
      "details": "Error: HTTPConnectionPool(host='localhost', port=5000): Max retries exceeded with url: /api/v2/ai/health (Caused by NewConnectionError('<urllib3.connection.HTTPConnection object at 0x0000017CA909C510>: Failed to establish a new connection: [WinError 10061] No se puede establecer una conexi\u00f3n ya que el equipo de destino deneg\u00f3 expresamente dicha conexi\u00f3n'))",
      "timestamp": "2025-08-29 20:21:21"
    },
    {
      "test": "AI Service",
      "status": "FAIL",
      "details": "Error probando IA: HTTPConnectionPool(host='localhost', port=5000): Max retries exceeded with url: /api/v2/ai/stats (Caused by NewConnectionError('<urllib3.connection.HTTPConnection object at 0x0000017CA8FC3410>: Failed to establish a new connection: [WinError 10061] No se puede establecer una conexi\u00f3n ya que el equipo de destino deneg\u00f3 expresamente dicha conexi\u00f3n'))",
      "timestamp": "2025-08-29 20:21:25"
    }
  ]
}